Workbook

Sheet 使い方
A1: 原価率計算シート（個人経営の飲食店向け）
A3: ■ このファイルでできること
A4: ・材料の仕入価格から、1g・1ml・1個あたりの単価を自動で計算します（歩留まりも考慮）。
A5: ・メニューごとに材料と使用量を入れると、1品の原価・原価率・目標との差・推奨売価が出ます。
A6: ・「一覧」シートで全メニュー（最大30品）の原価率を並べて確認できます。
A8: ■ 使う順番
A9: 1. 「設定」シートで、目標原価率と消費税率を確認します（初期値：目標30%、売価10%、仕入8%）。
A10: 2. 「材料マスタ」に材料を登録します（最大100件）。黄色のセル＝入力欄です（見出しに【入力】と書いてあります）。
A11: ・仕入価格は、レシートどおりの金額を入れ、「税込」か「税抜」を選びます（空欄は税込として扱います）。
A12: ・税率は空欄なら「設定」の仕入の税率（8%）を使います。容器など食品以外は10%を入れてください。
A13: ・内容量は、単位（g・ml・個・枚など）とそろえて数字で入れます。例：1kg袋なら 1000（単位 g）。
A14: ・歩留まりは、皮・骨・筋などを除いて実際に使える割合です。空欄は100%として扱います。85% または 85 と入力できます。
... A36: ・計算結果は入力した数字に基づく目安です。価格の決定は、ご自身の判断で行ってください。

Sheet 材料マスタ
A1: 材料マスタ
A2: 黄色＝入力欄（見出しに【入力】）、灰色＝自動計算（数式。消さないでください）。見本の行は見本の架空の数値です。
A3: 仕入価格はレシートどおりに入れ、税込か税抜かを選びます。空欄は税込として扱います。
A4: No | B4: 【入力】材料名 | C4: 【入力】仕入単位（メモ） | D4: 【入力】仕入価格（円） | E4: 【入力】税区分（税込／税抜） | F4: 【入力】税率（空欄=設定値） | G4: 【入力】内容量 | H4: 【入力】単位 | I4: 【入力】歩留まり（空欄=100%） | J4: 税抜仕入価格（円）［自動］ | K4: 単位あたり単価（税抜・円）［自動］ | L4: 歩留まり後の単価（税抜・円）［自動］ | M4: チェック［自動］
A5: 1 | B5: 豚こま切れ肉 | C5: 1kgパック | D5: 1280 | E5: 税込 | G5: 1000 | H5: g | J5: =IF(OR(B5="",D5=""),"",IFERROR(IF(E5="税抜",D5,ROUND(D5/(1+IF(F5="",'設定'!$C$6,IF(F5>=1,F5/100,F5))),2)),"")) | K5: =IFERROR(IF(OR(J5="",G5="",G5=0),"",ROUND(J5/G5,4)),"") | L5: =IFERROR(IF(K5="","",IF(IF(I5="",1,IF(I5>1,I5/100,I5))=0,"",ROUND(K5/IF(I5="",1,IF(I5>1,I5/100,I5)),4))),"") | M5: =IF(B5="","",IF(D5="","価格を入力",IF(OR(G5="",G5=0),"内容量を入力",IF(AND(I5<>"",I5=0),"歩留まりが0",IF(L5="","入力を確認","OK")))))
A6: 2 | B6: 鶏もも肉 | C6: 2kgパック | D6: 1980 | E6: 税抜 | G6: 2000 | H6: g | I6: 0.9 | J6: =IF(OR(B6="",D6=""),"",IFERROR(IF(E6="税抜",D6,ROUND(D6/(1+IF(F6="",'設定'!$C$6,IF(F6>=1,F6/100,F6))),2)),"")) | K6: =IFERROR(IF(OR(J6="",G6="",G6=0),"",ROUND(J6/G6,4)),"") | L6: =IFERROR(IF(K6="","",IF(IF(I6="",1,IF(I6>1,I6/100,I6))=0,"",ROUND(K6/IF(I6="",1,IF(I6>1,I6/100,I6)),4))),"") | M6: =IF(B6="","",IF(D6="","価格を入力",IF(OR(G6="",G6=0),"内容量を入力",IF(AND(I6<>"",I6=0),"歩留まりが0",IF(L6="","入力を確認","OK")))))
A7: 3 | B7: 玉ねぎ | C7: 3kg袋 | D7: 698 | E7: 税込 | G7: 3000 | H7: g | I7: 0.9 | J7: =IF(OR(B7="",D7=""),"",IFERROR(IF(E7="税抜",D7,ROUND(D7/(1+IF(F7="",'設定'!$C$6,IF(F7>=1,F7/100,F7))),2)),"")) | K7: =IFERROR(IF(OR(J7="",G7="",G7=0),"",ROUND(J7/G7,4)),"") | L7: =IFERROR(IF(K7="","",IF(IF(I7="",1,IF(I7>1,I7/100,I7))=0,"",ROUND(K7/IF(I7="",1,IF(I7>1,I7/100,I7)),4))),"") | M7: =IF(B7="","",IF(D7="","価格を入力",IF(OR(G7="",G7=0),"内容量を入力",IF(AND(I7<>"",I7=0),"歩留まりが0",IF(L7="","入力を確認","OK")))))
A8: 4 | B8: じゃがいも | C8: 1kg袋 | D8: 298 | E8: 税込 | G8: 1000 | H8: g | I8: 0.85 | J8: =IF(OR(B8="",D8=""),"",IFERROR(IF(E8="税抜",D8,ROUND(D8/(1+IF(F8="",'設定'!$C$6,IF(F8>=1,F8/100,F8))),2)),"")) | K8: =IFERROR(IF(OR(J8="",G8="",G8=0),"",ROUND(J8/G8,4)),"") | L8: =IFERROR(IF(K8="","",IF(IF(I8="",1,IF(I8>1,I8/100,I8))=0,"",ROUND(K8/IF(I8="",1,IF(I8>1,I8/100,I8)),4))),"") | M8: =IF(B8="","",IF(D8="","価格を入力",IF(OR(G8="",G8=0),"内容量を入力",IF(AND(I8<>"",I8=0),"歩留まりが0",IF(L8="","入力を確認","OK")))))
A9: 5 | B9: 卵 | C9: 10個パック | D9: 248 | E9: 税込 | G9: 10 | H9: 個 | J9: =IF(OR(B9="",D9=""),"",IFERROR(IF(E9="税抜",D9,ROUND(D9/(1+IF(F9="",'設定'!$C$6,IF(F9>=1,F9/100,F9))),2)),"")) | K9: =IFERROR(IF(OR(J9="",G9="",G9=0),"",ROUND(J9/G9,4)),"") | L9: =IFERROR(IF(K9="","",IF(IF(I9="",1,IF(I9>1,I9/100,I9))=0,"",ROUND(K9/IF(I9="",1,IF(I9>1,I9/100,I9)),4))),"") | M9: =IF(B9="","",IF(D9="","価格を入力",IF(OR(G9="",G9=0),"内容量を入力",IF(AND(I9<>"",I9=0),"歩留まりが0",IF(L9="","入力を確認","OK")))))
A10: 6 | B10: 米 | C10: 10kg袋 | D10: 4980 | E10: 税込 | G10: 10000 | H10: g | J10: =IF(OR(B10="",D10=""),"",IFERROR(IF(E10="税抜",D10,ROUND(D10/(1+IF(F10="",'設定'!$C$6,IF(F10>=1,F10/100,F10))),2)),"")) | K10: =IFERROR(IF(OR(J10="",G10="",G10=0),"",ROUND(J10/G10,4)),"") | L10: =IFERROR(IF(K10="","",IF(IF(I10="",1,IF(I10>1,I10/100,I10))=0,"",ROUND(K10/IF(I10="",1,IF(I10>1,I10/100,I10)),4))),"") | M10: =IF(B10="","",IF(D10="","価格を入力",IF(OR(G10="",G10=0),"内容量を入力",IF(AND(I10<>"",I10=0),"歩留まりが0",IF(L10="","入力を確認","OK")))))
A11: 7 | B11: キャベツ | C11: 1玉 | D11: 198 | E11: 税込 | G11: 1200 | H11: g | I11: 0.8 | J11: =IF(OR(B11="",D11=""),"",IFERROR(IF(E11="税抜",D11,ROUND(D11/(1+IF(F11="",'設定'!$C$6,IF(F11>=1,F11/100,F11))),2)),"")) | K11: =IFERROR(IF(OR(J11="",G11="",G11=0),"",ROUND(J11/G11,4)),"") | L11: =IFERROR(IF(K11="","",IF(IF(I11="",1,IF(I11>1,I11/100,I11))=0,"",ROUND(K11/IF(I11="",1,IF(I11>1,I11/100,I11)),4))),"") | M11: =IF(B11="","",IF(D11="","価格を入力",IF(OR(G11="",G11=0),"内容量を入力",IF(AND(I11<>"",I11=0),"歩留まりが0",IF(L11="","入力を確認","OK")))))
A12: 8 | B12: しょうゆ | C12: 1.8Lボトル | D12: 498 | E12: 税込 | G12: 1800 | H12: ml | J12: =IF(OR(B12="",D12=""),"",IFERROR(IF(E12="税抜",D12,ROUND(D12/(1+IF(F12="",'設定'!$C$6,IF(F12>=1,F12/100,F12))),2)),"")) | K12: =IFERROR(IF(OR(J12="",G12="",G12=0),"",ROUND(J12/G12,4)),"") | L12: =IFERROR(IF(K12="","",IF(IF(I12="",1,IF(I12>1,I12/100,I12))=0,"",ROUND(K12/IF(I12="",1,IF(I12>1,I12/100,I12)),4))),"") | M12: =IF(B12="","",IF(D12="","価格を入力",IF(OR(G12="",G12=0),"内容量を入力",IF(AND(I12<>"",I12=0),"歩留まりが0",IF(L12="","入力を確認","OK")))))
A13: 9 | B13: マヨネーズ | C13: 1kg袋 | D13: 598 | E13: 税抜 | G13: 1000 | H13: g | J13: =IF(OR(B13="",D13=""),"",IFERROR(IF(E13="税抜",D13,ROUND(D13/(1+IF(F13="",'設定'!$C$6,IF(F13>=1,F13/100,F13))),2)),"")) | K13: =IFERROR(IF(OR(J13="",G13="",G13=0),"",ROUND(J13/G13,4)),"") | L13: =IFERROR(IF(K13="","",IF(IF(I13="",1,IF(I13>1,I13/100,I13))=0,"",ROUND(K13/IF(I13="",1,IF(I13>1,I13/100,I13)),4))),"") | M13: =IF(B13="","",IF(D13="","価格を入力",IF(OR(G13="",G13=0),"内容量を入力",IF(AND(I13<>"",I13=0),"歩留まりが0",IF(L13="","入力を確認","OK")))))
A14: 10 | B14: 持ち帰り容器 | C14: 50枚入り | D14: 1100 | E14: 税込 | F14: 0.1 | G14: 50 | H14: 枚 | J14: =IF(OR(B14="",D14=""),"",IFERROR(IF(E14="税抜",D14,ROUND(D14/(1+IF(F14="",'設定'!$C$6,IF(F14>=1,F14/100,F14))),2)),"")) | K14: =IFERROR(IF(OR(J14="",G14="",G14=0),"",ROUND(J14/G14,4)),"") | L14: =IFERROR(IF(K14="","",IF(IF(I14="",1,IF(I14>1,I14/100,I14))=0,"",ROUND(K14/IF(I14="",1,IF(I14>1,I14/100,I14)),4))),"") | M14: =IF(B14="","",IF(D14="","価格を入力",IF(OR(G14="",G14=0),"内容量を入力",IF(AND(I14<>"",I14=0),"歩留まりが0",IF(L14="","入力を確認","OK")))))
A15: 11 | J15: =IF(OR(B15="",D15=""),"",IFERROR(IF(E15="税抜",D15,ROUND(D15/(1+IF(F15="",'設定'!$C$6,IF(F15>=1,F15/100,F15))),2)),"")) | K15: =IFERROR(IF(OR(J15="",G15="",G15=0),"",ROUND(J15/G15,4)),"") | L15: =IFERROR(IF(K15="","",IF(IF(I15="",1,IF(I15>1,I15/100,I15))=0,"",ROUND(K15/IF(I15="",1,IF(I15>1,I15/100,I15)),4))),"") | M15: =IF(B15="","",IF(D15="","価格を入力",IF(OR(G15="",G15=0),"内容量を入力",IF(AND(I15<>"",I15=0),"歩留まりが0",IF(L15="","入力を確認","OK")))))
A16: 12 | J16: =IF(OR(B16="",D16=""),"",IFERROR(IF(E16="税抜",D16,ROUND(D16/(1+IF(F16="",'設定'!$C$6,IF(F16>=1,F16/100,F16))),2)),"")) | K16: =IFERROR(IF(OR(J16="",G16="",G16=0),"",ROUND(J16/G16,4)),"") | L16: =IFERROR(IF(K16="","",IF(IF(I16="",1,IF(I16>1,I16/100,I16))=0,"",ROUND(K16/IF(I16="",1,IF(I16>1,I16/100,I16)),4))),"") | M16: =IF(B16="","",IF(D16="","価格を入力",IF(OR(G16="",G16=0),"内容量を入力",IF(AND(I16<>"",I16=0),"歩留まりが0",IF(L16="","入力を確認","OK")))))
A17: 13 | J17: =IF(OR(B17="",D17=""),"",IFERROR(IF(E17="税抜",D17,ROUND(D17/(1+IF(F17="",'設定'!$C$6,IF(F17>=1,F17/100,F17))),2)),"")) | K17: =IFERROR(IF(OR(J17="",G17="",G17=0),"",ROUND(J17/G17,4)),"") | L17: =IFERROR(IF(K17="","",IF(IF(I17="",1,IF(I17>1,I17/100,I17))=0,"",ROUND(K17/IF(I17="",1,IF(I17>1,I17/100,I17)),4))),"") | M17: =IF(B17="","",IF(D17="","価格を入力",IF(OR(G17="",G17=0),"内容量を入力",IF(AND(I17<>"",I17=0),"歩留まりが0",IF(L17="","入力を確認","OK")))))
A18: 14 | J18: =IF(OR(B18="",D18=""),"",IFERROR(IF(E18="税抜",D18,ROUND(D18/(1+IF(F18="",'設定'!$C$6,IF(F18>=1,F18/100,F18))),2)),"")) | K18: =IFERROR(IF(OR(J18="",G18="",G18=0),"",ROUND(J18/G18,4)),"") | L18: =IFERROR(IF(K18="","",IF(IF(I18="",1,IF(I18>1,I18/100,I18))=0,"",ROUND(K18/IF(I18="",1,IF(I18>1,I18/100,I18)),4))),"") | M18: =IF(B18="","",IF(D18="","価格を入力",IF(OR(G18="",G18=0),"内容量を入力",IF(AND(I18<>"",I18=0),"歩留まりが0",IF(L18="","入力を確認","OK")))))
A19: 15 | J19: =IF(OR(B19="",D19=""),"",IFERROR(IF(E19="税抜",D19,ROUND(D19/(1+IF(F19="",'設定'!$C$6,IF(F19>=1,F19/100,F19))),2)),"")) | K19: =IFERROR(IF(OR(J19="",G19="",G19=0),"",ROUND(J19/G19,4)),"") | L19: =IFERROR(IF(K19="","",IF(IF(I19="",1,IF(I19>1,I19/100,I19))=0,"",ROUND(K19/IF(I19="",1,IF(I19>1,I19/100,I19)),4))),"") | M19: =IF(B19="","",IF(D19="","価格を入力",IF(OR(G19="",G19=0),"内容量を入力",IF(AND(I19<>"",I19=0),"歩留まりが0",IF(L19="","入力を確認","OK")))))
A20: 16 | J20: =IF(OR(B20="",D20=""),"",IFERROR(IF(E20="税抜",D20,ROUND(D20/(1+IF(F20="",'設定'!$C$6,IF(F20>=1,F20/100,F20))),2)),"")) | K20: =IFERROR(IF(OR(J20="",G20="",G20=0),"",ROUND(J20/G20,4)),"") | L20: =IFERROR(IF(K20="","",IF(IF(I20="",1,IF(I20>1,I20/100,I20))=0,"",ROUND(K20/IF(I20="",1,IF(I20>1,I20/100,I20)),4))),"") | M20: =IF(B20="","",IF(D20="","価格を入力",IF(OR(G20="",G20=0),"内容量を入力",IF(AND(I20<>"",I20=0),"歩留まりが0",IF(L20="","入力を確認","OK")))))
A21: 17 | J21: =IF(OR(B21="",D21=""),"",IFERROR(IF(E21="税抜",D21,ROUND(D21/(1+IF(F21="",'設定'!$C$6,IF(F21>=1,F21/100,F21))),2)),"")) | K21: =IFERROR(IF(OR(J21="",G21="",G21=0),"",ROUND(J21/G21,4)),"") | L21: =IFERROR(IF(K21="","",IF(IF(I21="",1,IF(I21>1,I21/100,I21))=0,"",ROUND(K21/IF(I21="",1,IF(I21>1,I21/100,I21)),4))),"") | M21: =IF(B21="","",IF(D21="","価格を入力",IF(OR(G21="",G21=0),"内容量を入力",IF(AND(I21<>"",I21=0),"歩留まりが0",IF(L21="","入力を確認","OK")))))
A22: 18 | J22: =IF(OR(B22="",D22=""),"",IFERROR(IF(E22="税抜",D22,ROUND(D22/(1+IF(F22="",'設定'!$C$6,IF(F22>=1,F22/100,F22))),2)),"")) | K22: =IFERROR(IF(OR(J22="",G22="",G22=0),"",ROUND(J22/G22,4)),"") | L22: =IFERROR(IF(K22="","",IF(IF(I22="",1,IF(I22>1,I22/100,I22))=0,"",ROUND(K22/IF(I22="",1,IF(I22>1,I22/100,I22)),4))),"") | M22: =IF(B22="","",IF(D22="","価格を入力",IF(OR(G22="",G22=0),"内容量を入力",IF(AND(I22<>"",I22=0),"歩留まりが0",IF(L22="","入力を確認","OK")))))
A23: 19 | J23: =IF(OR(B23="",D23=""),"",IFERROR(IF(E23="税抜",D23,ROUND(D23/(1+IF(F23="",'設定'!$C$6,IF(F23>=1,F23/100,F23))),2)),"")) | K23: =IFERROR(IF(OR(J23="",G23="",G23=0),"",ROUND(J23/G23,4)),"") | L23: =IFERROR(IF(K23="","",IF(IF(I23="",1,IF(I23>1,I23/100,I23))=0,"",ROUND(K23/IF(I23="",1,IF(I23>1,I23/100,I23)),4))),"") | M23: =IF(B23="","",IF(D23="","価格を入力",IF(OR(G23="",G23=0),"内容量を入力",IF(AND(I23<>"",I23=0),"歩留まりが0",IF(L23="","入力を確認","OK")))))
A24: 20 | J24: =IF(OR(B24="",D24=""),"",IFERROR(IF(E24="税抜",D24,ROUND(D24/(1+IF(F24="",'設定'!$C$6,IF(F24>=1,F24/100,F24))),2)),"")) | K24: =IFERROR(IF(OR(J24="",G24="",G24=0),"",ROUND(J24/G24,4)),"") | L24: =IFERROR(IF(K24="","",IF(IF(I24="",1,IF(I24>1,I24/100,I24))=0,"",ROUND(K24/IF(I24="",1,IF(I24>1,I24/100,I24)),4))),"") | M24: =IF(B24="","",IF(D24="","価格を入力",IF(OR(G24="",G24=0),"内容量を入力",IF(AND(I24<>"",I24=0),"歩留まりが0",IF(L24="","入力を確認","OK")))))
A25: 21 | J25: =IF(OR(B25="",D25=""),"",IFERROR(IF(E25="税抜",D25,ROUND(D25/(1+IF(F25="",'設定'!$C$6,IF(F25>=1,F25/100,F25))),2)),"")) | K25: =IFERROR(IF(OR(J25="",G25="",G25=0),"",ROUND(J25/G25,4)),"") | L25: =IFERROR(IF(K25="","",IF(IF(I25="",1,IF(I25>1,I25/100,I25))=0,"",ROUND(K25/IF(I25="",1,IF(I25>1,I25/100,I25)),4))),"") | M25: =IF(B25="","",IF(D25="","価格を入力",IF(OR(G25="",G25=0),"内容量を入力",IF(AND(I25<>"",I25=0),"歩留まりが0",IF(L25="","入力を確認","OK")))))
A26: 22 | J26: =IF(OR(B26="",D26=""),"",IFERROR(IF(E26="税抜",D26,ROUND(D26/(1+IF(F26="",'設定'!$C$6,IF(F26>=1,F26/100,F26))),2)),"")) | K26: =IFERROR(IF(OR(J26="",G26="",G26=0),"",ROUND(J26/G26,4)),"") | L26: =IFERROR(IF(K26="","",IF(IF(I26="",1,IF(I26>1,I26/100,I26))=0,"",ROUND(K26/IF(I26="",1,IF(I26>1,I26/100,I26)),4))),"") | M26: =IF(B26="","",IF(D26="","価格を入力",IF(OR(G26="",G26=0),"内容量を入力",IF(AND(I26<>"",I26=0),"歩留まりが0",IF(L26="","入力を確認","OK")))))
... A104: 100 | J104: =IF(OR(B104="",D104=""),"",IFERROR(IF(E104="税抜",D104,ROUND(D104/(1+IF(F104="",'設定'!$C$6,IF(F104>=1,F104/100,F104))),2)),"")) | K104: =IFERROR(IF(OR(J104="",G104="",G104=0),"",ROUND(J104/G104,4)),"") | L104: =IFERROR(IF(K104="","",IF(IF(I104="",1,IF(I104>1,I104/100,I104))=0,"",ROUND(K104/IF(I104="",1,IF(I104>1,I104/100,I104)),4))),"") | M104: =IF(B104="","",IF(D104="","価格を入力",IF(OR(G104="",G104=0),"内容量を入力",IF(AND(I104<>"",I104=0),"歩留まりが0",IF(L104="","入力を確認","OK")))))

Sheet メニュー原価
A1: メニュー原価
A2: 黄色＝入力欄（【入力】）、灰色＝自動計算。原価・売価とも税抜で原価率を計算します。見本のメニューと金額は見本の架空の数値です。
A4: メニュー1 | B4: 【入力】メニュー名 | C4: 豚のしょうが焼き定食（見本）
B5: 【入力】販売価格（税込・円） | C5: 980 | D5: 【入力】目標原価率（空欄=設定値） | F5: 【入力】売価の税率（空欄=設定値）
A6: No | B6: 【入力】材料名（リストから選ぶ） | C6: 【入力】使用量 | D6: 単位［自動］ | E6: 単価（税抜・円/単位）［自動］ | F6: 原価（円）［自動］ | G6: チェック［自動］
A7: 1 | B7: 豚こま切れ肉 | C7: 120 | D7: =IF(B7="","",IFERROR(VLOOKUP(B7,'材料マスタ'!$B$5:$L$104,7,FALSE)&"","")) | E7: =IF(B7="","",IFERROR(VLOOKUP(B7,'材料マスタ'!$B$5:$L$104,11,FALSE),"")) | F7: =IF(OR(B7="",C7=""),"",IFERROR(ROUND(C7*E7,2),"")) | G7: =IF(B7="","",IFERROR(IF(VLOOKUP(B7,'材料マスタ'!$B$5:$L$104,11,FALSE)="","材料マスタを確認",IF(C7="","使用量を入力","OK")),"未登録の材料"))
A8: 2 | B8: 玉ねぎ | C8: 50 | D8: =IF(B8="","",IFERROR(VLOOKUP(B8,'材料マスタ'!$B$5:$L$104,7,FALSE)&"","")) | E8: =IF(B8="","",IFERROR(VLOOKUP(B8,'材料マスタ'!$B$5:$L$104,11,FALSE),"")) | F8: =IF(OR(B8="",C8=""),"",IFERROR(ROUND(C8*E8,2),"")) | G8: =IF(B8="","",IFERROR(IF(VLOOKUP(B8,'材料マスタ'!$B$5:$L$104,11,FALSE)="","材料マスタを確認",IF(C8="","使用量を入力","OK")),"未登録の材料"))
A9: 3 | B9: キャベツ | C9: 60 | D9: =IF(B9="","",IFERROR(VLOOKUP(B9,'材料マスタ'!$B$5:$L$104,7,FALSE)&"","")) | E9: =IF(B9="","",IFERROR(VLOOKUP(B9,'材料マスタ'!$B$5:$L$104,11,FALSE),"")) | F9: =IF(OR(B9="",C9=""),"",IFERROR(ROUND(C9*E9,2),"")) | G9: =IF(B9="","",IFERROR(IF(VLOOKUP(B9,'材料マスタ'!$B$5:$L$104,11,FALSE)="","材料マスタを確認",IF(C9="","使用量を入力","OK")),"未登録の材料"))
A10: 4 | B10: しょうゆ | C10: 15 | D10: =IF(B10="","",IFERROR(VLOOKUP(B10,'材料マスタ'!$B$5:$L$104,7,FALSE)&"","")) | E10: =IF(B10="","",IFERROR(VLOOKUP(B10,'材料マスタ'!$B$5:$L$104,11,FALSE),"")) | F10: =IF(OR(B10="",C10=""),"",IFERROR(ROUND(C10*E10,2),"")) | G10: =IF(B10="","",IFERROR(IF(VLOOKUP(B10,'材料マスタ'!$B$5:$L$104,11,FALSE)="","材料マスタを確認",IF(C10="","使用量を入力","OK")),"未登録の材料"))
A11: 5 | B11: 米 | C11: 150 | D11: =IF(B11="","",IFERROR(VLOOKUP(B11,'材料マスタ'!$B$5:$L$104,7,FALSE)&"","")) | E11: =IF(B11="","",IFERROR(VLOOKUP(B11,'材料マスタ'!$B$5:$L$104,11,FALSE),"")) | F11: =IF(OR(B11="",C11=""),"",IFERROR(ROUND(C11*E11,2),"")) | G11: =IF(B11="","",IFERROR(IF(VLOOKUP(B11,'材料マスタ'!$B$5:$L$104,11,FALSE)="","材料マスタを確認",IF(C11="","使用量を入力","OK")),"未登録の材料"))
A12: 6 | D12: =IF(B12="","",IFERROR(VLOOKUP(B12,'材料マスタ'!$B$5:$L$104,7,FALSE)&"","")) | E12: =IF(B12="","",IFERROR(VLOOKUP(B12,'材料マスタ'!$B$5:$L$104,11,FALSE),"")) | F12: =IF(OR(B12="",C12=""),"",IFERROR(ROUND(C12*E12,2),"")) | G12: =IF(B12="","",IFERROR(IF(VLOOKUP(B12,'材料マスタ'!$B$5:$L$104,11,FALSE)="","材料マスタを確認",IF(C12="","使用量を入力","OK")),"未登録の材料"))
A13: 7 | D13: =IF(B13="","",IFERROR(VLOOKUP(B13,'材料マスタ'!$B$5:$L$104,7,FALSE)&"","")) | E13: =IF(B13="","",IFERROR(VLOOKUP(B13,'材料マスタ'!$B$5:$L$104,11,FALSE),"")) | F13: =IF(OR(B13="",C13=""),"",IFERROR(ROUND(C13*E13,2),"")) | G13: =IF(B13="","",IFERROR(IF(VLOOKUP(B13,'材料マスタ'!$B$5:$L$104,11,FALSE)="","材料マスタを確認",IF(C13="","使用量を入力","OK")),"未登録の材料"))
A14: 8 | D14: =IF(B14="","",IFERROR(VLOOKUP(B14,'材料マスタ'!$B$5:$L$104,7,FALSE)&"","")) | E14: =IF(B14="","",IFERROR(VLOOKUP(B14,'材料マスタ'!$B$5:$L$104,11,FALSE),"")) | F14: =IF(OR(B14="",C14=""),"",IFERROR(ROUND(C14*E14,2),"")) | G14: =IF(B14="","",IFERROR(IF(VLOOKUP(B14,'材料マスタ'!$B$5:$L$104,11,FALSE)="","材料マスタを確認",IF(C14="","使用量を入力","OK")),"未登録の材料"))
A15: 9 | D15: =IF(B15="","",IFERROR(VLOOKUP(B15,'材料マスタ'!$B$5:$L$104,7,FALSE)&"","")) | E15: =IF(B15="","",IFERROR(VLOOKUP(B15,'材料マスタ'!$B$5:$L$104,11,FALSE),"")) | F15: =IF(OR(B15="",C15=""),"",IFERROR(ROUND(C15*E15,2),"")) | G15: =IF(B15="","",IFERROR(IF(VLOOKUP(B15,'材料マスタ'!$B$5:$L$104,11,FALSE)="","材料マスタを確認",IF(C15="","使用量を入力","OK")),"未登録の材料"))
A16: 10 | D16: =IF(B16="","",IFERROR(VLOOKUP(B16,'材料マスタ'!$B$5:$L$104,7,FALSE)&"","")) | E16: =IF(B16="","",IFERROR(VLOOKUP(B16,'材料マスタ'!$B$5:$L$104,11,FALSE),"")) | F16: =IF(OR(B16="",C16=""),"",IFERROR(ROUND(C16*E16,2),"")) | G16: =IF(B16="","",IFERROR(IF(VLOOKUP(B16,'材料マスタ'!$B$5:$L$104,11,FALSE)="","材料マスタを確認",IF(C16="","使用量を入力","OK")),"未登録の材料"))
A17: 11 | D17: =IF(B17="","",IFERROR(VLOOKUP(B17,'材料マスタ'!$B$5:$L$104,7,FALSE)&"","")) | E17: =IF(B17="","",IFERROR(VLOOKUP(B17,'材料マスタ'!$B$5:$L$104,11,FALSE),"")) | F17: =IF(OR(B17="",C17=""),"",IFERROR(ROUND(C17*E17,2),"")) | G17: =IF(B17="","",IFERROR(IF(VLOOKUP(B17,'材料マスタ'!$B$5:$L$104,11,FALSE)="","材料マスタを確認",IF(C17="","使用量を入力","OK")),"未登録の材料"))
A18: 12 | D18: =IF(B18="","",IFERROR(VLOOKUP(B18,'材料マスタ'!$B$5:$L$104,7,FALSE)&"","")) | E18: =IF(B18="","",IFERROR(VLOOKUP(B18,'材料マスタ'!$B$5:$L$104,11,FALSE),"")) | F18: =IF(OR(B18="",C18=""),"",IFERROR(ROUND(C18*E18,2),"")) | G18: =IF(B18="","",IFERROR(IF(VLOOKUP(B18,'材料マスタ'!$B$5:$L$104,11,FALSE)="","材料マスタを確認",IF(C18="","使用量を入力","OK")),"未登録の材料"))
A19: 13 | D19: =IF(B19="","",IFERROR(VLOOKUP(B19,'材料マスタ'!$B$5:$L$104,7,FALSE)&"","")) | E19: =IF(B19="","",IFERROR(VLOOKUP(B19,'材料マスタ'!$B$5:$L$104,11,FALSE),"")) | F19: =IF(OR(B19="",C19=""),"",IFERROR(ROUND(C19*E19,2),"")) | G19: =IF(B19="","",IFERROR(IF(VLOOKUP(B19,'材料マスタ'!$B$5:$L$104,11,FALSE)="","材料マスタを確認",IF(C19="","使用量を入力","OK")),"未登録の材料"))
A20: 14 | D20: =IF(B20="","",IFERROR(VLOOKUP(B20,'材料マスタ'!$B$5:$L$104,7,FALSE)&"","")) | E20: =IF(B20="","",IFERROR(VLOOKUP(B20,'材料マスタ'!$B$5:$L$104,11,FALSE),"")) | F20: =IF(OR(B20="",C20=""),"",IFERROR(ROUND(C20*E20,2),"")) | G20: =IF(B20="","",IFERROR(IF(VLOOKUP(B20,'材料マスタ'!$B$5:$L$104,11,FALSE)="","材料マスタを確認",IF(C20="","使用量を入力","OK")),"未登録の材料"))
A21: 15 | D21: =IF(B21="","",IFERROR(VLOOKUP(B21,'材料マスタ'!$B$5:$L$104,7,FALSE)&"","")) | E21: =IF(B21="","",IFERROR(VLOOKUP(B21,'材料マスタ'!$B$5:$L$104,11,FALSE),"")) | F21: =IF(OR(B21="",C21=""),"",IFERROR(ROUND(C21*E21,2),"")) | G21: =IF(B21="","",IFERROR(IF(VLOOKUP(B21,'材料マスタ'!$B$5:$L$104,11,FALSE)="","材料マスタを確認",IF(C21="","使用量を入力","OK")),"未登録の材料"))
B22: 合計原価（税抜・円） | C22: =SUM(F7:F21)
B23: 目標原価率（適用値） | C23: =IF(E5="",'設定'!$C$4,IF(E5>1,E5/100,E5))
B24: 売価の税率（適用値） | C24: =IF(G5="",'設定'!$C$5,IF(G5>=1,G5/100,G5))
B25: 税抜売価（円） | C25: =IF(C5="","",IFERROR(ROUND(C5/(1+C24),2),""))
B26: 原価率 | C26: =IFERROR(IF(OR(C25="",C25=0),"",ROUND(C22/C25,4)),"") | D26: 判定［自動］ | E26: =IF(C26="",IF(C4="","","売価を入力"),IF(C26>C23,"超過","目標内"))
B27: 目標との差（＋は目標超過） | C27: =IF(C26="","",ROUND(C26-C23,4))
B28: 推奨売価（税込・円／目標原価率から逆算、10円単位で切り上げ） | C28: =IFERROR(IF(OR(C22=0,C23=0),"",ROUNDUP(ROUND(C22/C23*(1+C24),2)/10,0)*10),"")
A29: メニュー2 | B29: 【入力】メニュー名 | C29: 親子丼（見本）
B30: 【入力】販売価格（税込・円） | C30: 780 | D30: 【入力】目標原価率（空欄=設定値） | F30: 【入力】売価の税率（空欄=設定値）
A31: No | B31: 【入力】材料名（リストから選ぶ） | C31: 【入力】使用量 | D31: 単位［自動］ | E31: 単価（税抜・円/単位）［自動］ | F31: 原価（円）［自動］ | G31: チェック［自動］
A32: 1 | B32: 鶏もも肉 | C32: 100 | D32: =IF(B32="","",IFERROR(VLOOKUP(B32,'材料マスタ'!$B$5:$L$104,7,FALSE)&"","")) | E32: =IF(B32="","",IFERROR(VLOOKUP(B32,'材料マスタ'!$B$5:$L$104,11,FALSE),"")) | F32: =IF(OR(B32="",C32=""),"",IFERROR(ROUND(C32*E32,2),"")) | G32: =IF(B32="","",IFERROR(IF(VLOOKUP(B32,'材料マスタ'!$B$5:$L$104,11,FALSE)="","材料マスタを確認",IF(C32="","使用量を入力","OK")),"未登録の材料"))
A33: 2 | B33: 卵 | C33: 2 | D33: =IF(B33="","",IFERROR(VLOOKUP(B33,'材料マスタ'!$B$5:$L$104,7,FALSE)&"","")) | E33: =IF(B33="","",IFERROR(VLOOKUP(B33,'材料マスタ'!$B$5:$L$104,11,FALSE),"")) | F33: =IF(OR(B33="",C33=""),"",IFERROR(ROUND(C33*E33,2),"")) | G33: =IF(B33="","",IFERROR(IF(VLOOKUP(B33,'材料マスタ'!$B$5:$L$104,11,FALSE)="","材料マスタを確認",IF(C33="","使用量を入力","OK")),"未登録の材料"))
A34: 3 | B34: 玉ねぎ | C34: 40 | D34: =IF(B34="","",IFERROR(VLOOKUP(B34,'材料マスタ'!$B$5:$L$104,7,FALSE)&"","")) | E34: =IF(B34="","",IFERROR(VLOOKUP(B34,'材料マスタ'!$B$5:$L$104,11,FALSE),"")) | F34: =IF(OR(B34="",C34=""),"",IFERROR(ROUND(C34*E34,2),"")) | G34: =IF(B34="","",IFERROR(IF(VLOOKUP(B34,'材料マスタ'!$B$5:$L$104,11,FALSE)="","材料マスタを確認",IF(C34="","使用量を入力","OK")),"未登録の材料"))
A35: 4 | B35: しょうゆ | C35: 15 | D35: =IF(B35="","",IFERROR(VLOOKUP(B35,'材料マスタ'!$B$5:$L$104,7,FALSE)&"","")) | E35: =IF(B35="","",IFERROR(VLOOKUP(B35,'材料マスタ'!$B$5:$L$104,11,FALSE),"")) | F35: =IF(OR(B35="",C35=""),"",IFERROR(ROUND(C35*E35,2),"")) | G35: =IF(B35="","",IFERROR(IF(VLOOKUP(B35,'材料マスタ'!$B$5:$L$104,11,FALSE)="","材料マスタを確認",IF(C35="","使用量を入力","OK")),"未登録の材料"))
A36: 5 | B36: 米 | C36: 150 | D36: =IF(B36="","",IFERROR(VLOOKUP(B36,'材料マスタ'!$B$5:$L$104,7,FALSE)&"","")) | E36: =IF(B36="","",IFERROR(VLOOKUP(B36,'材料マスタ'!$B$5:$L$104,11,FALSE),"")) | F36: =IF(OR(B36="",C36=""),"",IFERROR(ROUND(C36*E36,2),"")) | G36: =IF(B36="","",IFERROR(IF(VLOOKUP(B36,'材料マスタ'!$B$5:$L$104,11,FALSE)="","材料マスタを確認",IF(C36="","使用量を入力","OK")),"未登録の材料"))
A37: 6 | D37: =IF(B37="","",IFERROR(VLOOKUP(B37,'材料マスタ'!$B$5:$L$104,7,FALSE)&"","")) | E37: =IF(B37="","",IFERROR(VLOOKUP(B37,'材料マスタ'!$B$5:$L$104,11,FALSE),"")) | F37: =IF(OR(B37="",C37=""),"",IFERROR(ROUND(C37*E37,2),"")) | G37: =IF(B37="","",IFERROR(IF(VLOOKUP(B37,'材料マスタ'!$B$5:$L$104,11,FALSE)="","材料マスタを確認",IF(C37="","使用量を入力","OK")),"未登録の材料"))
A38: 7 | D38: =IF(B38="","",IFERROR(VLOOKUP(B38,'材料マスタ'!$B$5:$L$104,7,FALSE)&"","")) | E38: =IF(B38="","",IFERROR(VLOOKUP(B38,'材料マスタ'!$B$5:$L$104,11,FALSE),"")) | F38: =IF(OR(B38="",C38=""),"",IFERROR(ROUND(C38*E38,2),"")) | G38: =IF(B38="","",IFERROR(IF(VLOOKUP(B38,'材料マスタ'!$B$5:$L$104,11,FALSE)="","材料マスタを確認",IF(C38="","使用量を入力","OK")),"未登録の材料"))
A39: 8 | D39: =IF(B39="","",IFERROR(VLOOKUP(B39,'材料マスタ'!$B$5:$L$104,7,FALSE)&"","")) | E39: =IF(B39="","",IFERROR(VLOOKUP(B39,'材料マスタ'!$B$5:$L$104,11,FALSE),"")) | F39: =IF(OR(B39="",C39=""),"",IFERROR(ROUND(C39*E39,2),"")) | G39: =IF(B39="","",IFERROR(IF(VLOOKUP(B39,'材料マスタ'!$B$5:$L$104,11,FALSE)="","材料マスタを確認",IF(C39="","使用量を入力","OK")),"未登録の材料"))
A40: 9 | D40: =IF(B40="","",IFERROR(VLOOKUP(B40,'材料マスタ'!$B$5:$L$104,7,FALSE)&"","")) | E40: =IF(B40="","",IFERROR(VLOOKUP(B40,'材料マスタ'!$B$5:$L$104,11,FALSE),"")) | F40: =IF(OR(B40="",C40=""),"",IFERROR(ROUND(C40*E40,2),"")) | G40: =IF(B40="","",IFERROR(IF(VLOOKUP(B40,'材料マスタ'!$B$5:$L$104,11,FALSE)="","材料マスタを確認",IF(C40="","使用量を入力","OK")),"未登録の材料"))
A41: 10 | D41: =IF(B41="","",IFERROR(VLOOKUP(B41,'材料マスタ'!$B$5:$L$104,7,FALSE)&"","")) | E41: =IF(B41="","",IFERROR(VLOOKUP(B41,'材料マスタ'!$B$5:$L$104,11,FALSE),"")) | F41: =IF(OR(B41="",C41=""),"",IFERROR(ROUND(C41*E41,2),"")) | G41: =IF(B41="","",IFERROR(IF(VLOOKUP(B41,'材料マスタ'!$B$5:$L$104,11,FALSE)="","材料マスタを確認",IF(C41="","使用量を入力","OK")),"未登録の材料"))
...

Sheet 一覧
A1: 一覧（全メニューの原価率）
A2: このシートは自動で表示されます（入力は不要）。判定が「超過」の品は、目標原価率を超えています。
A3: 店名：〇〇食堂（見本）／見本の数値はすべて架空です。
A4: No | B4: メニュー名 | C4: 販売価格（税込・円） | D4: 合計原価（税抜・円） | E4: 原価率 | F4: 目標原価率 | G4: 目標との差 | H4: 判定 | I4: 推奨売価（税込・円）
A5: 1 | B5: =IF('メニュー原価'!C4="","",'メニュー原価'!C4) | C5: =IF('メニュー原価'!C4="","",IF('メニュー原価'!C5="","",'メニュー原価'!C5)) | D5: =IF('メニュー原価'!C4="","",IF('メニュー原価'!C22="","",'メニュー原価'!C22)) | E5: =IF('メニュー原価'!C4="","",IF('メニュー原価'!C26="","",'メニュー原価'!C26)) | F5: =IF('メニュー原価'!C4="","",IF('メニュー原価'!C23="","",'メニュー原価'!C23)) | G5: =IF('メニュー原価'!C4="","",IF('メニュー原価'!C27="","",'メニュー原価'!C27)) | H5: =IF('メニュー原価'!C4="","",IF('メニュー原価'!E26="","",'メニュー原価'!E26)) | I5: =IF('メニュー原価'!C4="","",IF('メニュー原価'!C28="","",'メニュー原価'!C28))
A6: 2 | B6: =IF('メニュー原価'!C29="","",'メニュー原価'!C29) | C6: =IF('メニュー原価'!C29="","",IF('メニュー原価'!C30="","",'メニュー原価'!C30)) | D6: =IF('メニュー原価'!C29="","",IF('メニュー原価'!C47="","",'メニュー原価'!C47)) | E6: =IF('メニュー原価'!C29="","",IF('メニュー原価'!C51="","",'メニュー原価'!C51)) | F6: =IF('メニュー原価'!C29="","",IF('メニュー原価'!C48="","",'メニュー原価'!C48)) | G6: =IF('メニュー原価'!C29="","",IF('メニュー原価'!C52="","",'メニュー原価'!C52)) | H6: =IF('メニュー原価'!C29="","",IF('メニュー原価'!E51="","",'メニュー原価'!E51)) | I6: =IF('メニュー原価'!C29="","",IF('メニュー原価'!C53="","",'メニュー原価'!C53))
A7: 3 | B7: =IF('メニュー原価'!C54="","",'メニュー原価'!C54) | C7: =IF('メニュー原価'!C54="","",IF('メニュー原価'!C55="","",'メニュー原価'!C55)) | D7: =IF('メニュー原価'!C54="","",IF('メニュー原価'!C72="","",'メニュー原価'!C72)) | E7: =IF('メニュー原価'!C54="","",IF('メニュー原価'!C76="","",'メニュー原価'!C76)) | F7: =IF('メニュー原価'!C54="","",IF('メニュー原価'!C73="","",'メニュー原価'!C73)) | G7: =IF('メニュー原価'!C54="","",IF('メニュー原価'!C77="","",'メニュー原価'!C77)) | H7: =IF('メニュー原価'!C54="","",IF('メニュー原価'!E76="","",'メニュー原価'!E76)) | I7: =IF('メニュー原価'!C54="","",IF('メニュー原価'!C78="","",'メニュー原価'!C78))
A8: 4 | B8: =IF('メニュー原価'!C79="","",'メニュー原価'!C79) | C8: =IF('メニュー原価'!C79="","",IF('メニュー原価'!C80="","",'メニュー原価'!C80)) | D8: =IF('メニュー原価'!C79="","",IF('メニュー原価'!C97="","",'メニュー原価'!C97)) | E8: =IF('メニュー原価'!C79="","",IF('メニュー原価'!C101="","",'メニュー原価'!C101)) | F8: =IF('メニュー原価'!C79="","",IF('メニュー原価'!C98="","",'メニュー原価'!C98)) | G8: =IF('メニュー原価'!C79="","",IF('メニュー原価'!C102="","",'メニュー原価'!C102)) | H8: =IF('メニュー原価'!C79="","",IF('メニュー原価'!E101="","",'メニュー原価'!E101)) | I8: =IF('メニュー原価'!C79="","",IF('メニュー原価'!C103="","",'メニュー原価'!C103))
A9: 5 | B9: =IF('メニュー原価'!C104="","",'メニュー原価'!C104) | C9: =IF('メニュー原価'!C104="","",IF('メニュー原価'!C105="","",'メニュー原価'!C105)) | D9: =IF('メニュー原価'!C104="","",IF('メニュー原価'!C122="","",'メニュー原価'!C122)) | E9: =IF('メニュー原価'!C104="","",IF('メニュー原価'!C126="","",'メニュー原価'!C126)) | F9: =IF('メニュー原価'!C104="","",IF('メニュー原価'!C123="","",'メニュー原価'!C123)) | G9: =IF('メニュー原価'!C104="","",IF('メニュー原価'!C127="","",'メニュー原価'!C127)) | H9: =IF('メニュー原価'!C104="","",IF('メニュー原価'!E126="","",'メニュー原価'!E126)) | I9: =IF('メニュー原価'!C104="","",IF('メニュー原価'!C128="","",'メニュー原価'!C128))
A10: 6 | B10: =IF('メニュー原価'!C129="","",'メニュー原価'!C129) | C10: =IF('メニュー原価'!C129="","",IF('メニュー原価'!C130="","",'メニュー原価'!C130)) | D10: =IF('メニュー原価'!C129="","",IF('メニュー原価'!C147="","",'メニュー原価'!C147)) | E10: =IF('メニュー原価'!C129="","",IF('メニュー原価'!C151="","",'メニュー原価'!C151)) | F10: =IF('メニュー原価'!C129="","",IF('メニュー原価'!C148="","",'メニュー原価'!C148)) | G10: =IF('メニュー原価'!C129="","",IF('メニュー原価'!C152="","",'メニュー原価'!C152)) | H10: =IF('メニュー原価'!C129="","",IF('メニュー原価'!E151="","",'メニュー原価'!E151)) | I10: =IF('メニュー原価'!C129="","",IF('メニュー原価'!C153="","",'メニュー原価'!C153))
A11: 7 | B11: =IF('メニュー原価'!C154="","",'メニュー原価'!C154) | C11: =IF('メニュー原価'!C154="","",IF('メニュー原価'!C155="","",'メニュー原価'!C155)) | D11: =IF('メニュー原価'!C154="","",IF('メニュー原価'!C172="","",'メニュー原価'!C172)) | E11: =IF('メニュー原価'!C154="","",IF('メニュー原価'!C176="","",'メニュー原価'!C176)) | F11: =IF('メニュー原価'!C154="","",IF('メニュー原価'!C173="","",'メニュー原価'!C173)) | G11: =IF('メニュー原価'!C154="","",IF('メニュー原価'!C177="","",'メニュー原価'!C177)) | H11: =IF('メニュー原価'!C154="","",IF('メニュー原価'!E176="","",'メニュー原価'!E176)) | I11: =IF('メニュー原価'!C154="","",IF('メニュー原価'!C178="","",'メニュー原価'!C178))
A12: 8 | B12: =IF('メニュー原価'!C179="","",'メニュー原価'!C179) | C12: =IF('メニュー原価'!C179="","",IF('メニュー原価'!C180="","",'メニュー原価'!C180)) | D12: =IF('メニュー原価'!C179="","",IF('メニュー原価'!C197="","",'メニュー原価'!C197)) | E12: =IF('メニュー原価'!C179="","",IF('メニュー原価'!C201="","",'メニュー原価'!C201)) | F12: =IF('メニュー原価'!C179="","",IF('メニュー原価'!C198="","",'メニュー原価'!C198)) | G12: =IF('メニュー原価'!C179="","",IF('メニュー原価'!C202="","",'メニュー原価'!C202)) | H12: =IF('メニュー原価'!C179="","",IF('メニュー原価'!E201="","",'メニュー原価'!E201)) | I12: =IF('メニュー原価'!C179="","",IF('メニュー原価'!C203="","",'メニュー原価'!C203))
A13: 9 | B13: =IF('メニュー原価'!C204="","",'メニュー原価'!C204) | C13: =IF('メニュー原価'!C204="","",IF('メニュー原価'!C205="","",'メニュー原価'!C205)) | D13: =IF('メニュー原価'!C204="","",IF('メニュー原価'!C222="","",'メニュー原価'!C222)) | E13: =IF('メニュー原価'!C204="","",IF('メニュー原価'!C226="","",'メニュー原価'!C226)) | F13: =IF('メニュー原価'!C204="","",IF('メニュー原価'!C223="","",'メニュー原価'!C223)) | G13: =IF('メニュー原価'!C204="","",IF('メニュー原価'!C227="","",'メニュー原価'!C227)) | H13: =IF('メニュー原価'!C204="","",IF('メニュー原価'!E226="","",'メニュー原価'!E226)) | I13: =IF('メニュー原価'!C204="","",IF('メニュー原価'!C228="","",'メニュー原価'!C228))
A14: 10 | B14: =IF('メニュー原価'!C229="","",'メニュー原価'!C229) | C14: =IF('メニュー原価'!C229="","",IF('メニュー原価'!C230="","",'メニュー原価'!C230)) | D14: =IF('メニュー原価'!C229="","",IF('メニュー原価'!C247="","",'メニュー原価'!C247)) | E14: =IF('メニュー原価'!C229="","",IF('メニュー原価'!C251="","",'メニュー原価'!C251)) | F14: =IF('メニュー原価'!C229="","",IF('メニュー原価'!C248="","",'メニュー原価'!C248)) | G14: =IF('メニュー原価'!C229="","",IF('メニュー原価'!C252="","",'メニュー原価'!C252)) | H14: =IF('メニュー原価'!C229="","",IF('メニュー原価'!E251="","",'メニュー原価'!E251)) | I14: =IF('メニュー原価'!C229="","",IF('メニュー原価'!C253="","",'メニュー原価'!C253))
A15: 11 | B15: =IF('メニュー原価'!C254="","",'メニュー原価'!C254) | C15: =IF('メニュー原価'!C254="","",IF('メニュー原価'!C255="","",'メニュー原価'!C255)) | D15: =IF('メニュー原価'!C254="","",IF('メニュー原価'!C272="","",'メニュー原価'!C272)) | E15: =IF('メニュー原価'!C254="","",IF('メニュー原価'!C276="","",'メニュー原価'!C276)) | F15: =IF('メニュー原価'!C254="","",IF('メニュー原価'!C273="","",'メニュー原価'!C273)) | G15: =IF('メニュー原価'!C254="","",IF('メニュー原価'!C277="","",'メニュー原価'!C277)) | H15: =IF('メニュー原価'!C254="","",IF('メニュー原価'!E276="","",'メニュー原価'!E276)) | I15: =IF('メニュー原価'!C254="","",IF('メニュー原価'!C278="","",'メニュー原価'!C278))
A16: 12 | B16: =IF('メニュー原価'!C279="","",'メニュー原価'!C279) | C16: =IF('メニュー原価'!C279="","",IF('メニュー原価'!C280="","",'メニュー原価'!C280)) | D16: =IF('メニュー原価'!C279="","",IF('メニュー原価'!C297="","",'メニュー原価'!C297)) | E16: =IF('メニュー原価'!C279="","",IF('メニュー原価'!C301="","",'メニュー原価'!C301)) | F16: =IF('メニュー原価'!C279="","",IF('メニュー原価'!C298="","",'メニュー原価'!C298)) | G16: =IF('メニュー原価'!C279="","",IF('メニュー原価'!C302="","",'メニュー原価'!C302)) | H16: =IF('メニュー原価'!C279="","",IF('メニュー原価'!E301="","",'メニュー原価'!E301)) | I16: =IF('メニュー原価'!C279="","",IF('メニュー原価'!C303="","",'メニュー原価'!C303))
A17: 13 | B17: =IF('メニュー原価'!C304="","",'メニュー原価'!C304) | C17: =IF('メニュー原価'!C304="","",IF('メニュー原価'!C305="","",'メニュー原価'!C305)) | D17: =IF('メニュー原価'!C304="","",IF('メニュー原価'!C322="","",'メニュー原価'!C322)) | E17: =IF('メニュー原価'!C304="","",IF('メニュー原価'!C326="","",'メニュー原価'!C326)) | F17: =IF('メニュー原価'!C304="","",IF('メニュー原価'!C323="","",'メニュー原価'!C323)) | G17: =IF('メニュー原価'!C304="","",IF('メニュー原価'!C327="","",'メニュー原価'!C327)) | H17: =IF('メニュー原価'!C304="","",IF('メニュー原価'!E326="","",'メニュー原価'!E326)) | I17: =IF('メニュー原価'!C304="","",IF('メニュー原価'!C328="","",'メニュー原価'!C328))
A18: 14 | B18: =IF('メニュー原価'!C329="","",'メニュー原価'!C329) | C18: =IF('メニュー原価'!C329="","",IF('メニュー原価'!C330="","",'メニュー原価'!C330)) | D18: =IF('メニュー原価'!C329="","",IF('メニュー原価'!C347="","",'メニュー原価'!C347)) | E18: =IF('メニュー原価'!C329="","",IF('メニュー原価'!C351="","",'メニュー原価'!C351)) | F18: =IF('メニュー原価'!C329="","",IF('メニュー原価'!C348="","",'メニュー原価'!C348)) | G18: =IF('メニュー原価'!C329="","",IF('メニュー原価'!C352="","",'メニュー原価'!C352)) | H18: =IF('メニュー原価'!C329="","",IF('メニュー原価'!E351="","",'メニュー原価'!E351)) | I18: =IF('メニュー原価'!C329="","",IF('メニュー原価'!C353="","",'メニュー原価'!C353))
A19: 15 | B19: =IF('メニュー原価'!C354="","",'メニュー原価'!C354) | C19: =IF('メニュー原価'!C354="","",IF('メニュー原価'!C355="","",'メニュー原価'!C355)) | D19: =IF('メニュー原価'!C354="","",IF('メニュー原価'!C372="","",'メニュー原価'!C372)) | E19: =IF('メニュー原価'!C354="","",IF('メニュー原価'!C376="","",'メニュー原価'!C376)) | F19: =IF('メニュー原価'!C354="","",IF('メニュー原価'!C373="","",'メニュー原価'!C373)) | G19: =IF('メニュー原価'!C354="","",IF('メニュー原価'!C377="","",'メニュー原価'!C377)) | H19: =IF('メニュー原価'!C354="","",IF('メニュー原価'!E376="","",'メニュー原価'!E376)) | I19: =IF('メニュー原価'!C354="","",IF('メニュー原価'!C378="","",'メニュー原価'!C378))
A20: 16 | B20: =IF('メニュー原価'!C379="","",'メニュー原価'!C379) | C20: =IF('メニュー原価'!C379="","",IF('メニュー原価'!C380="","",'メニュー原価'!C380)) | D20: =IF('メニュー原価'!C379="","",IF('メニュー原価'!C397="","",'メニュー原価'!C397)) | E20: =IF('メニュー原価'!C379="","",IF('メニュー原価'!C401="","",'メニュー原価'!C401)) | F20: =IF('メニュー原価'!C379="","",IF('メニュー原価'!C398="","",'メニュー原価'!C398)) | G20: =IF('メニュー原価'!C379="","",IF('メニュー原価'!C402="","",'メニュー原価'!C402)) | H20: =IF('メニュー原価'!C379="","",IF('メニュー原価'!E401="","",'メニュー原価'!E401)) | I20: =IF('メニュー原価'!C379="","",IF('メニュー原価'!C403="","",'メニュー原価'!C403))
A21: 17 | B21: =IF('メニュー原価'!C404="","",'メニュー原価'!C404) | C21: =IF('メニュー原価'!C404="","",IF('メニュー原価'!C405="","",'メニュー原価'!C405)) | D21: =IF('メニュー原価'!C404="","",IF('メニュー原価'!C422="","",'メニュー原価'!C422)) | E21: =IF('メニュー原価'!C404="","",IF('メニュー原価'!C426="","",'メニュー原価'!C426)) | F21: =IF('メニュー原価'!C404="","",IF('メニュー原価'!C423="","",'メニュー原価'!C423)) | G21: =IF('メニュー原価'!C404="","",IF('メニュー原価'!C427="","",'メニュー原価'!C427)) | H21: =IF('メニュー原価'!C404="","",IF('メニュー原価'!E426="","",'メニュー原価'!E426)) | I21: =IF('メニュー原価'!C404="","",IF('メニュー原価'!C428="","",'メニュー原価'!C428))
A22: 18 | B22: =IF('メニュー原価'!C429="","",'メニュー原価'!C429) | C22: =IF('メニュー原価'!C429="","",IF('メニュー原価'!C430="","",'メニュー原価'!C430)) | D22: =IF('メニュー原価'!C429="","",IF('メニュー原価'!C447="","",'メニュー原価'!C447)) | E22: =IF('メニュー原価'!C429="","",IF('メニュー原価'!C451="","",'メニュー原価'!C451)) | F22: =IF('メニュー原価'!C429="","",IF('メニュー原価'!C448="","",'メニュー原価'!C448)) | G22: =IF('メニュー原価'!C429="","",IF('メニュー原価'!C452="","",'メニュー原価'!C452)) | H22: =IF('メニュー原価'!C429="","",IF('メニュー原価'!E451="","",'メニュー原価'!E451)) | I22: =IF('メニュー原価'!C429="","",IF('メニュー原価'!C453="","",'メニュー原価'!C453))
A23: 19 | B23: =IF('メニュー原価'!C454="","",'メニュー原価'!C454) | C23: =IF('メニュー原価'!C454="","",IF('メニュー原価'!C455="","",'メニュー原価'!C455)) | D23: =IF('メニュー原価'!C454="","",IF('メニュー原価'!C472="","",'メニュー原価'!C472)) | E23: =IF('メニュー原価'!C454="","",IF('メニュー原価'!C476="","",'メニュー原価'!C476)) | F23: =IF('メニュー原価'!C454="","",IF('メニュー原価'!C473="","",'メニュー原価'!C473)) | G23: =IF('メニュー原価'!C454="","",IF('メニュー原価'!C477="","",'メニュー原価'!C477)) | H23: =IF('メニュー原価'!C454="","",IF('メニュー原価'!E476="","",'メニュー原価'!E476)) | I23: =IF('メニュー原価'!C454="","",IF('メニュー原価'!C478="","",'メニュー原価'!C478))
A24: 20 | B24: =IF('メニュー原価'!C479="","",'メニュー原価'!C479) | C24: =IF('メニュー原価'!C479="","",IF('メニュー原価'!C480="","",'メニュー原価'!C480)) | D24: =IF('メニュー原価'!C479="","",IF('メニュー原価'!C497="","",'メニュー原価'!C497)) | E24: =IF('メニュー原価'!C479="","",IF('メニュー原価'!C501="","",'メニュー原価'!C501)) | F24: =IF('メニュー原価'!C479="","",IF('メニュー原価'!C498="","",'メニュー原価'!C498)) | G24: =IF('メニュー原価'!C479="","",IF('メニュー原価'!C502="","",'メニュー原価'!C502)) | H24: =IF('メニュー原価'!C479="","",IF('メニュー原価'!E501="","",'メニュー原価'!E501)) | I24: =IF('メニュー原価'!C479="","",IF('メニュー原価'!C503="","",'メニュー原価'!C503))
A25: 21 | B25: =IF('メニュー原価'!C504="","",'メニュー原価'!C504) | C25: =IF('メニュー原価'!C504="","",IF('メニュー原価'!C505="","",'メニュー原価'!C505)) | D25: =IF('メニュー原価'!C504="","",IF('メニュー原価'!C522="","",'メニュー原価'!C522)) | E25: =IF('メニュー原価'!C504="","",IF('メニュー原価'!C526="","",'メニュー原価'!C526)) | F25: =IF('メニュー原価'!C504="","",IF('メニュー原価'!C523="","",'メニュー原価'!C523)) | G25: =IF('メニュー原価'!C504="","",IF('メニュー原価'!C527="","",'メニュー原価'!C527)) | H25: =IF('メニュー原価'!C504="","",IF('メニュー原価'!E526="","",'メニュー原価'!E526)) | I25: =IF('メニュー原価'!C504="","",IF('メニュー原価'!C528="","",'メニュー原価'!C528))
A26: 22 | B26: =IF('メニュー原価'!C529="","",'メニュー原価'!C529) | C26: =IF('メニュー原価'!C529="","",IF('メニュー原価'!C530="","",'メニュー原価'!C530)) | D26: =IF('メニュー原価'!C529="","",IF('メニュー原価'!C547="","",'メニュー原価'!C547)) | E26: =IF('メニュー原価'!C529="","",IF('メニュー原価'!C551="","",'メニュー原価'!C551)) | F26: =IF('メニュー原価'!C529="","",IF('メニュー原価'!C548="","",'メニュー原価'!C548)) | G26: =IF('メニュー原価'!C529="","",IF('メニュー原価'!C552="","",'メニュー原価'!C552)) | H26: =IF('メニュー原価'!C529="","",IF('メニュー原価'!E551="","",'メニュー原価'!E551)) | I26: =IF('メニュー原価'!C529="","",IF('メニュー原価'!C553="","",'メニュー原価'!C553))
A27: 23 | B27: =IF('メニュー原価'!C554="","",'メニュー原価'!C554) | C27: =IF('メニュー原価'!C554="","",IF('メニュー原価'!C555="","",'メニュー原価'!C555)) | D27: =IF('メニュー原価'!C554="","",IF('メニュー原価'!C572="","",'メニュー原価'!C572)) | E27: =IF('メニュー原価'!C554="","",IF('メニュー原価'!C576="","",'メニュー原価'!C576)) | F27: =IF('メニュー原価'!C554="","",IF('メニュー原価'!C573="","",'メニュー原価'!C573)) | G27: =IF('メニュー原価'!C554="","",IF('メニュー原価'!C577="","",'メニュー原価'!C577)) | H27: =IF('メニュー原価'!C554="","",IF('メニュー原価'!E576="","",'メニュー原価'!E576)) | I27: =IF('メニュー原価'!C554="","",IF('メニュー原価'!C578="","",'メニュー原価'!C578))
A28: 24 | B28: =IF('メニュー原価'!C579="","",'メニュー原価'!C579) | C28: =IF('メニュー原価'!C579="","",IF('メニュー原価'!C580="","",'メニュー原価'!C580)) | D28: =IF('メニュー原価'!C579="","",IF('メニュー原価'!C597="","",'メニュー原価'!C597)) | E28: =IF('メニュー原価'!C579="","",IF('メニュー原価'!C601="","",'メニュー原価'!C601)) | F28: =IF('メニュー原価'!C579="","",IF('メニュー原価'!C598="","",'メニュー原価'!C598)) | G28: =IF('メニュー原価'!C579="","",IF('メニュー原価'!C602="","",'メニュー原価'!C602)) | H28: =IF('メニュー原価'!C579="","",IF('メニュー原価'!E601="","",'メニュー原価'!E601)) | I28: =IF('メニュー原価'!C579="","",IF('メニュー原価'!C603="","",'メニュー原価'!C603))
A29: 25 | B29: =IF('メニュー原価'!C604="","",'メニュー原価'!C604) | C29: =IF('メニュー原価'!C604="","",IF('メニュー原価'!C605="","",'メニュー原価'!C605)) | D29: =IF('メニュー原価'!C604="","",IF('メニュー原価'!C622="","",'メニュー原価'!C622)) | E29: =IF('メニュー原価'!C604="","",IF('メニュー原価'!C626="","",'メニュー原価'!C626)) | F29: =IF('メニュー原価'!C604="","",IF('メニュー原価'!C623="","",'メニュー原価'!C623)) | G29: =IF('メニュー原価'!C604="","",IF('メニュー原価'!C627="","",'メニュー原価'!C627)) | H29: =IF('メニュー原価'!C604="","",IF('メニュー原価'!E626="","",'メニュー原価'!E626)) | I29: =IF('メニュー原価'!C604="","",IF('メニュー原価'!C628="","",'メニュー原価'!C628))
A30: 26 | B30: =IF('メニュー原価'!C629="","",'メニュー原価'!C629) | C30: =IF('メニュー原価'!C629="","",IF('メニュー原価'!C630="","",'メニュー原価'!C630)) | D30: =IF('メニュー原価'!C629="","",IF('メニュー原価'!C647="","",'メニュー原価'!C647)) | E30: =IF('メニュー原価'!C629="","",IF('メニュー原価'!C651="","",'メニュー原価'!C651)) | F30: =IF('メニュー原価'!C629="","",IF('メニュー原価'!C648="","",'メニュー原価'!C648)) | G30: =IF('メニュー原価'!C629="","",IF('メニュー原価'!C652="","",'メニュー原価'!C652)) | H30: =IF('メニュー原価'!C629="","",IF('メニュー原価'!E651="","",'メニュー原価'!E651)) | I30: =IF('メニュー原価'!C629="","",IF('メニュー原価'!C653="","",'メニュー原価'!C653))
A31: 27 | B31: =IF('メニュー原価'!C654="","",'メニュー原価'!C654) | C31: =IF('メニュー原価'!C654="","",IF('メニュー原価'!C655="","",'メニュー原価'!C655)) | D31: =IF('メニュー原価'!C654="","",IF('メニュー原価'!C672="","",'メニュー原価'!C672)) | E31: =IF('メニュー原価'!C654="","",IF('メニュー原価'!C676="","",'メニュー原価'!C676)) | F31: =IF('メニュー原価'!C654="","",IF('メニュー原価'!C673="","",'メニュー原価'!C673)) | G31: =IF('メニュー原価'!C654="","",IF('メニュー原価'!C677="","",'メニュー原価'!C677)) | H31: =IF('メニュー原価'!C654="","",IF('メニュー原価'!E676="","",'メニュー原価'!E676)) | I31: =IF('メニュー原価'!C654="","",IF('メニュー原価'!C678="","",'メニュー原価'!C678))
A32: 28 | B32: =IF('メニュー原価'!C679="","",'メニュー原価'!C679) | C32: =IF('メニュー原価'!C679="","",IF('メニュー原価'!C680="","",'メニュー原価'!C680)) | D32: =IF('メニュー原価'!C679="","",IF('メニュー原価'!C697="","",'メニュー原価'!C697)) | E32: =IF('メニュー原価'!C679="","",IF('メニュー原価'!C701="","",'メニュー原価'!C701)) | F32: =IF('メニュー原価'!C679="","",IF('メニュー原価'!C698="","",'メニュー原価'!C698)) | G32: =IF('メニュー原価'!C679="","",IF('メニュー原価'!C702="","",'メニュー原価'!C702)) | H32: =IF('メニュー原価'!C679="","",IF('メニュー原価'!E701="","",'メニュー原価'!E701)) | I32: =IF('メニュー原価'!C679="","",IF('メニュー原価'!C703="","",'メニュー原価'!C703))
A33: 29 | B33: =IF('メニュー原価'!C704="","",'メニュー原価'!C704) | C33: =IF('メニュー原価'!C704="","",IF('メニュー原価'!C705="","",'メニュー原価'!C705)) | D33: =IF('メニュー原価'!C704="","",IF('メニュー原価'!C722="","",'メニュー原価'!C722)) | E33: =IF('メニュー原価'!C704="","",IF('メニュー原価'!C726="","",'メニュー原価'!C726)) | F33: =IF('メニュー原価'!C704="","",IF('メニュー原価'!C723="","",'メニュー原価'!C723)) | G33: =IF('メニュー原価'!C704="","",IF('メニュー原価'!C727="","",'メニュー原価'!C727)) | H33: =IF('メニュー原価'!C704="","",IF('メニュー原価'!E726="","",'メニュー原価'!E726)) | I33: =IF('メニュー原価'!C704="","",IF('メニュー原価'!C728="","",'メニュー原価'!C728))
A34: 30 | B34: =IF('メニュー原価'!C729="","",'メニュー原価'!C729) | C34: =IF('メニュー原価'!C729="","",IF('メニュー原価'!C730="","",'メニュー原価'!C730)) | D34: =IF('メニュー原価'!C729="","",IF('メニュー原価'!C747="","",'メニュー原価'!C747)) | E34: =IF('メニュー原価'!C729="","",IF('メニュー原価'!C751="","",'メニュー原価'!C751)) | F34: =IF('メニュー原価'!C729="","",IF('メニュー原価'!C748="","",'メニュー原価'!C748)) | G34: =IF('メニュー原価'!C729="","",IF('メニュー原価'!C752="","",'メニュー原価'!C752)) | H34: =IF('メニュー原価'!C729="","",IF('メニュー原価'!E751="","",'メニュー原価'!E751)) | I34: =IF('メニュー原価'!C729="","",IF('メニュー原価'!C753="","",'メニュー原価'!C753))

Sheet 設定
B1: 設定
B2: 店名：〇〇食堂（見本）
B3: 項目 | C3: 【入力】値 | D3: 説明
B4: 目標原価率 | C4: 0.3 | D4: メニューごとに空欄のときに使う目標。30% または 30 と入力できます。
B5: 売価の消費税率 | C5: 0.1 | D5: 販売価格（税込）を税抜に直すときの税率。店内飲食は10%。
B6: 仕入の消費税率（初期値） | C6: 0.08 | D6: 材料マスタの税率が空欄のときに使う税率。食品は8%。
B9: 見本の数値はすべて架空です。
B10: 税区分のリスト（消さないでください）
B11: 税込
B12: 税抜
